Workbook

Sheet Cover
C27: School Name: | F27: Alice Vail
C30: Fall Semester Visit: | F30: 45925
C31: Lead Coordinator: | F31: Tawnee Arrieta
C33: Spring Semester Visit:
C34: Lead Coordinator:
C41: This document is used to collect trend data. It is not an evaluation tool.
C42: The TUSD Walkthrough Form will be used to gather data.

Sheet Checklist
A1: TUSD School Walkthrough Checklist
A3: This walkthrough is part of the monitor & evaluate strategy found in the district and school IAPs. The goal of this walkthrough is to gather summary data that the principal & school can use as part of the school improvement process. The TUSD Walkthrough Form will be used to gather data.
A5: School Responsibility • Provide a working space for the team to meet. • Develop a walkthrough schedule allowing each class to be visited once for about 15 minutes and a 5 minute debrief. Only 3 classes per hour. Team size will vary depending on school size and participants.
A7: Introductions/Purpose (30 minutes) • Introductions of all group members • Coordinator: State the purpose of the visit, “This document is used to collect trend data. It is not an evaluation tool. The TUSD Walkthrough Form will be used to gather data for the principal & school.” • Principal shares: Current Highlights at the school. • Principal shares: Initiatives, strategies, and areas that they would like the team to be aware of and focus on: (i.e., engagement, levels of questioning, Teacher Clarity, AVID strategies) • Let's Review the walkthrough process, observation instrument • Pass out and review the TUSD Walkthrough Form. Be sure to share the following: • There are 7 categories, one more than the previous year. Classroom Environment was added. • Even with the changes the walkthrough instrument is still about 75% based on Danielson indicators. • Rather than rating proficiency, you will be looking for evidence of each indicator. Document your evidence. • Remind participants that they will collect evidence from each classroom and reach consensus scores for each indicator. • New this year is the addition of program-specific walkthrough indicators, which will be completed by department experts. • Coordinator: Take a moment and share the QR code for the state standards website prior to starting the walkthrough.
A9: Walkthrough (2 hours & 0 minutes max) • We will visit classrooms for 15 minutes and use the TUSD Observational Instrument to collect evidence for all 7 categories. Department representatives will follow the same time frame but will complete specific indicators. • After each observation, teams will have 5 minutes to discuss the evidence gathered and reach a consensus score. If department-specific team has more than one representative, they will also take 5 minutes to reach their own consensus score. • Remind teams that a category can receive a score of a zero (0). There should be no N/As. • Once all observations are complete or if return time is approaching, teams should make their way back to the meeting room.
A11: Debrief Meeting (30 minutes) • Collect consensus scores from each team and department/program scores. • Use your discretion on time allotted to share. • Each team will share walkthrough trends and 1 to 2 praise and probe/push statements. • Begin with department experts; once the trends are shared and department narrative is complete, they may be dismissed. • Proceed with the remaining teams, gathering trends along with praise and probe/push statements. • Share scores and graphs with group. • The principal will be invited to reflect on the walk-through data and share the next steps. • Thank everyone for their time and participation. Collect all walkthrough observational instruments.
A13: Post Walkthrough • Share school folder with the principal to access Walkthrough Data and Debrief form. • The principal will have the option to later share walkthrough data or discuss trends with staff at their discretion.

Sheet Fall - Data
A1: Fall Semester Walkthrough | D1: School: | E1: =Cover!F27 -> Alice Vail | G1: Date: | H1: =Cover!F30 -> 45925
A4: CORE | B4: Classroom Environment | C4: Learning Expectations | D4: Student Thinking, Problem Solving, Voice | E4: Engaging Students in Learning | F4: Assessment in Instruction | G4: Flexibility and Responsiveness | H4: Integrity of Core Curriculum | I4: Culturally Relevant | J4: Culturally Relevant Curriculum | K4: CR Pedagogy, Critical Thinking | L4: Positive Learning Community | M4: Student Identity and Voice | N4: Language Acquisition | O4: English Language Development | P4: Cultural Responsiveness | Q4: Student Grouping, Language Use | R4: Career & Tech Education | S4: Classroom Instruction | T4: Lab Instruction | U4: Exceptional Education | V4: Classroom Instruction | W4: Magnet | X4: Instructional Focus | Y4: Magnet Specific | Z4: Community Engagement | AA4: Two-Way Dual Language | AB4: Language Development | AC4: Cultural Competence
A5: Indicators Average Score | B5: =IFERROR(TEXT(AVERAGE(B9:B42),"##.00")&" out of 4","No Data") -> 3.60 out of 4 | C5: =IFERROR(TEXT(AVERAGE(C9:C42),"##.00")&" out of 6","No Data") -> 5.00 out of 6 | D5: =IFERROR(TEXT(AVERAGE(D9:D42),"##.00")&" out of 5","No Data") -> 2.80 out of 5 | E5: =IFERROR(TEXT(AVERAGE(E9:E42),"##.00")&" out of 6","No Data") -> 4.30 out of 6 | F5: =IFERROR(TEXT(AVERAGE(F9:F42),"##.00")&" out of 4","No Data") -> 2.40 out of 4 | G5: =IFERROR(TEXT(AVERAGE(G9:G42),"##.00")&" out of 5","No Data") -> 3.10 out of 5 | H5: =IFERROR(TEXT(AVERAGE(H9:H42),"##.00")&" out of 3","No Data") -> 2.80 out of 3 | J5: =IFERROR(TEXT(AVERAGE(J9:J42),"##.00")&" out of 5","No Data") -> No Data | K5: =IFERROR(TEXT(AVERAGE(K9:K42),"##.00")&" out of 4","No Data") -> No Data | L5: =IFERROR(TEXT(AVERAGE(L9:L42),"##.00")&" out of 2","No Data") -> No Data | M5: =IFERROR(TEXT(AVERAGE(M9:M42),"##.00")&" out of 2","No Data") -> No Data | O5: =IFERROR(TEXT(AVERAGE(O9:O42),"##.00")&" out of 4","No Data") -> 2.50 out of 4 | P5: =IFERROR(TEXT(AVERAGE(P9:P42),"##.00")&" out of 2","No Data") -> 1.00 out of 2 | Q5: =IFERROR(TEXT(AVERAGE(Q9:Q42),"##.00")&" out of 2","No Data") -> 1.00 out of 2 | S5: =IFERROR(TEXT(AVERAGE(S9:S42),"##.00")&" out of 3","No Data") -> No Data | T5: =IFERROR(TEXT(AVERAGE(T9:T42),"##.00")&" out of 3","No Data") -> No Data | V5: =IFERROR(TEXT(AVERAGE(V9:V42),"##.00")&" out of 2","No Data") -> 1.50 out of 2 | X5: =IFERROR(TEXT(AVERAGE(X9:X42),"##.00")&" out of 5","No Data") -> No Data | Y5: =IFERROR(TEXT(AVERAGE(Y9:Y42),"##.00")&" out of 3","No Data") -> No Data | Z5: =IFERROR(TEXT(AVERAGE(Z9:Z42),"##.00")&" out of 2","No Data") -> No Data | AB5: =IFERROR(TEXT(AVERAGE(AB9:AB42),"##.00")&" out of 5","No Data") -> No Data | AC5: =IFERROR(TEXT(AVERAGE(AC9:AC42),"##.00")&" out of 4","No Data") -> No Data
A6: % of Indicators Observed | B6: =IFERROR(AVERAGE(B9:B42)/4,"No Data") -> 0.9 | C6: =IFERROR(AVERAGE(C9:C42)/6,"No Data") -> 0.83333333 | D6: =IFERROR(AVERAGE(D9:D42)/5,"No Data") -> 0.56 | E6: =IFERROR(AVERAGE(E9:E42)/6,"No Data") -> 0.71666667 | F6: =IFERROR(AVERAGE(F9:F42)/4,"No Data") -> 0.6 | G6: =IFERROR(AVERAGE(G9:G42)/5,"No Data") -> 0.62 | H6: =IFERROR(AVERAGE(H9:H42)/3,"No Data") -> 0.93333333 | J6: =IFERROR(AVERAGE(J9:J42)/5,"No Data") -> No Data | K6: =IFERROR(AVERAGE(K9:K42)/4,"No Data") -> No Data | L6: =IFERROR(AVERAGE(L9:L42)/2,"No Data") -> No Data | M6: =IFERROR(AVERAGE(M9:M42)/2,"No Data") -> No Data | O6: =IFERROR(AVERAGE(O9:O42)/4,"No Data") -> 0.625 | P6: =IFERROR(AVERAGE(P9:P42)/2,"No Data") -> 0.5 | Q6: =IFERROR(AVERAGE(Q9:Q42)/2,"No Data") -> 0.5 | S6: =IFERROR(AVERAGE(S9:S42)/3,"No Data") -> No Data | T6: =IFERROR(AVERAGE(T9:T42)/3,"No Data") -> No Data | V6: =IFERROR(AVERAGE(V9:V42)/2,"No Data") -> 0.75 | X6: =IFERROR(AVERAGE(X9:X42)/5,"No Data") -> No Data | Y6: =IFERROR(AVERAGE(Y9:Y42)/3,"No Data") -> No Data | Z6: =IFERROR(AVERAGE(Z9:Z42)/2,"No Data") -> No Data | AB6: =IFERROR(AVERAGE(AB9:AB42)/5,"No Data") -> No Data | AC6: =IFERROR(AVERAGE(AC9:AC42)/4,"No Data") -> No Data
A8: CORE | B8: Classroom Environment (#of indicators = 0-4) | C8: Learning Expectations (# of Indicators = 0-6) | D8: Student Thinking, Problem Solving, Voice (# of Indicators = 0-5) | E8: Engaging Students in Learning (# of Indicators = 0-6) | F8: Assessment in Instruction (# of Indicators = 0-4) | G8: Flexibility and Responsiveness (# of Indicators = 0-5) | H8: Integrity of Core Curriculum (# of Indicators = 0-3) | I8: Culturally Relevant | J8: Culturally Relevant Curriculum (#of Indicators= 0-5) | K8: CR Pedagogy, Critical Thinking (#of Indicators 0-4) | L8: Positive Learning Community (#of Indicators 0-2) | M8: Student Identity and Voice (#of Indicators 0-2) | N8: Language Acquisition | O8: English Language Development (ELD) Instruction = 0-4) | P8: Cultural Responsiveness (#of Indicators 0-2) | Q8: Student Grouping, Language Use (#of Indicators 0-2) | R8: Career & Tech Education | S8: Classroom Instruction (#of Indicators= 0-3) | T8: Lab Instruction (#of Indicators 0-3) | U8: Exceptional Education | V8: Classroom Instruction (#of Indicators= 0-2) | W8: Magnet | X8: Instructional Focus (#of Indicators= 0-5) | Y8: Magnet Specific (#of Indicators 0-3) | Z8: Community Engagement (#of Indicators 0-2) | AA8: Two-Way Dual Language | AB8: Language Development (#of Indicators= 0-5) | AC8: Cultural Competence (#of Indicators 0-4)
A9: Classroom 1 | B9: 4 | C9: 6 | D9: 4 | E9: 6 | F9: 3 | G9: 4 | H9: 3 | O9: 3 | P9: 1 | Q9: 1 | V9: 1
A10: Classroom 2 | B10: 3 | C10: 0 | D10: 1 | E10: 2 | F10: 1 | G10: 2 | H10: 3 | O10: 2 | P10: 1 | Q10: 1 | V10: 2
A11: Classroom 3 | B11: 4 | C11: 6 | D11: 4 | E11: 6 | F11: 2 | G11: 5 | H11: 3
A12: Classroom 4 | B12: 4 | C12: 6 | D12: 3 | E12: 5 | F12: 2 | G12: 2 | H12: 3
A13: Classroom 5 | B13: 3 | C13: 6 | D13: 2 | E13: 0 | F13: 1 | G13: 2 | H13: 3
A14: Classroom 6 | B14: 4 | C14: 6 | D14: 3 | E14: 6 | F14: 3 | G14: 4 | H14: 3
A15: Classroom 7 | B15: 4 | C15: 6 | D15: 5 | E15: 6 | F15: 4 | G15: 5 | H15: 3
A16: Classroom 8 | B16: 4 | C16: 3 | D16: 1 | E16: 2 | F16: 2 | G16: 2 | H16: 3
A17: Classroom 9 | B17: 3 | C17: 6 | D17: 2 | E17: 4 | F17: 2 | G17: 1 | H17: 2
A18: Classroom 10 | B18: 3 | C18: 5 | D18: 3 | E18: 6 | F18: 4 | G18: 4 | H18: 2
A19: Classroom 11
A20: Classroom 12
A21: Classroom 13
A22: Classroom 14
A23: Classroom 15
A24: Classroom 16
A25: Classroom 17
A26: Classroom 18
A27: Classroom 19
A28: Classroom 20
A29: Classroom 21
A30: Classroom 22
... A42: Classroom 34
A43: Total Percent Earned | B43: =B6 -> 0.9 | C43: =C6 -> 0.83333333 | D43: =D6 -> 0.56 | E43: =E6 -> 0.71666667 | F43: =F6 -> 0.6 | G43: =G6 -> 0.62 | H43: =H6 -> 0.93333333 | J43: =J6 -> No Data | K43: =K6 -> No Data | L43: =L6 -> No Data | M43: =M6 -> No Data | O43: =O6 -> 0.625 | P43: =P6 -> 0.5 | Q43: =Q6 -> 0.5 | S43: =S6 -> No Data | T43: =T6 -> No Data | V43: =V6 -> 0.75 | X43: =X6 -> No Data | Y43: =Y6 -> No Data | Z43: =Z6 -> No Data | AB43: =AB6 -> No Data | AC43: =AC6 -> No Data

Sheet Fall- Report
A1: District Walkthrough - Report
A2: =_xlfn.CONCAT("School: ",Cover!F27) -> School: Alice Vail | B2: =Cover!F30 -> 45925
A4: CORE CATEGORIES - TEAM SUMMARY
A5: Classroom Environment | B5: =IFERROR('Fall - Data'!B6,"No Data") -> 0.9
A6: Learning Expectations | B6: =IFERROR('Fall - Data'!C6,"No Data") -> 0.83333333
A7: Student Thinking, Problem Solving, Voice | B7: =IFERROR('Fall - Data'!D6,"No Data") -> 0.56
A8: Engaging Students in Learning | B8: =IFERROR('Fall - Data'!E6,"No Data") -> 0.71666667
A9: Assessment in Instruction | B9: =IFERROR('Fall - Data'!F6,"No Data") -> 0.6
A10: Flexibility and Responsiveness | B10: =IFERROR('Fall - Data'!G6,"No Data") -> 0.62
A11: Integrity of Core Curriculum | B11: =IFERROR('Fall - Data'!H6,"No Data") -> 0.93333333
A12: PRAISE | B12: PROBE & PUSH
A13: *Learning Targets and Success criteria. Student engagement. Great rapport between teachers and students. Peer to peer interactions | B13: * Possibly using sentence frames to get to higher levels of DOK in conversations. Have students read and annotate their texts.
A14: *Student friendly language in learning targets and success criteria. Enaggement in small group instructions. Attentiveness to all students. Repeated instructions that needed one on one checks. Very inclusive settings. | B14: *How can students learn to praise one another in the same way that staff does? Have students be able to answer the "why". How could teachers address metacognition? Improving sytructures and procedures -- timer could be helpful in this.
A15: *Excellent collaborative study groups. Classroom management strategies and very positive tone and respect with students. Classroom routines and procedures on point. Very positive learning environments and teacher clarity strategies. Fidelity to curriculum across the board. | B15: *More circulating the classeoom instead of staying in one part of the classroom. More opportunities for student choice. Suggestion to make sure each student in the group has an assigned role. Reflecting on success criteria throughout lesson.
A16: PRINCIPAL REFLECTION & NEXT STEPS
A17: Principal Highlights First year implementing the teaming model—starting slowly to ensure everything is done with care, and the team has already shown strong collaboration. Teachers have been given the gift of time to collaborate, which has supported shared planning and consistency. Long-term goal is to transition into a full 7th–8th grade teaming school, providing a powerful way to guide students through the middle school process and prepare them for high school. Parent involvement has been a highlight, with families actively engaged and supportive. Hosting PLCs in the conference room with all teachers has allowed for shared resources and data, keeping information organized and accessible for accountability and instructional planning. Principal Reflection Expressed pride in seeing teacher training translate into strong classroom practice. Teachers’ hard work is evident, and collaboration among peers has been a key factor in this success. Positive praise and thoughtful questioning have proven to be valuable strategies, helping sustain a supportive learning culture. Additionally, the new PLC structure has enhanced collaboration, making it easier to track progress and maintain a consistent focus on student outcomes.
A18: LANGUAGE ACQUISITION - TEAM SUMMARY
A19: English Language Development Instruction | B19: ='Fall - Data'!O6 -> 0.625
A20: Cultural Responsiveness | B20: ='Fall - Data'!P6 -> 0.5
A21: Student Grouping and Language Use | B21: ='Fall - Data'!Q6 -> 0.5
A22: PRAISE | B22: PROBE & PUSH
A23: Lesson pacing was appropriate, and English Learners were clearly identified within content classes. Consistent use of the Get Ready! curriculum supported instruction. Opportunities for student agency and choice were evident. | B23: Post ELD standards alongside content standards and provide consistent linguistic supports to ensure English Learners can fully access instruction. Use intentional grouping strategies that promote both language development and content learning. Leverage students’ home languages through visuals, graphic organizers, and opportunities to write or brainstorm in their first language.
A24: DEPARTMENT NARRATIVE
A25: During the visit, classrooms observed were Science and ELD. In two of the three classrooms, learning targets and success criteria were clearly posted, providing evidence of teacher clarity and alignment to objectives. Across classrooms, student-centered approaches and fidelity to the adopted curriculum were evident, and students were engaged in group learning opportunities. Tier 1 instructional strategies were observed; however, instruction could be further enhanced by incorporating more strategies such as turn-and-talk or think-pair-share to increase student interaction and academic discourse. Notable strengths included appropriate lesson pacing and intentional identification of English Learners within content classes. The use of the Get Ready! curriculum supported structured lessons and access to grade-level content. Recommendations include posting ELD standards alongside general content standards to ensure targeted support for English Learners. Teachers are encouraged to remain mindful of who their EL students are and to provide consistent linguistic supports throughout instruction. Grouping strategies should be considered carefully to ensure that students are placed in ways that promote both language and content development. Finally, there are opportunities to more intentionally leverage students’ home languages—for example, through the use of graphic organizers with visuals and by allowing students to write or brainstorm in their home language as a bridge to English learning.
A26: EXCEPTIONAL EDUCATION - TEAM SUMMARY
A27: Classroom Instruction | B27: ='Fall - Data'!V6 -> 0.75
A28: PRAISE | B28: PROBE & PUSH
A29: Consistent use of learning targets and success criteria across classrooms. High levels of student engagement observed in both inclusion and social studies settings. Strong modeling of positive reinforcement by staff, fostering a supportive classroom environment. | B29: Expand opportunities for student voice, encouraging students not only to participate but also to provide feedback, share ideas, and support one another with peer-to-peer praise. Model and explicitly teach metacognitive strategies so students can begin to explain how they learn and why strategies are effective, building independence as thinkers. Strengthen classroom structures and routines—such as using timers or clear procedural cues—to improve pacing, transitions, and student accountability.
A30: DEPARTMENT NARRATIVE
A31: During the observation of two inclusion classes and one social studies class, there was clear evidence of consistent learning targets, success criteria, and high levels of student engagement. Teachers provided strong models of positive reinforcement, consistently praising students and fostering a supportive learning environment. An opportunity for growth is to extend this practice by teaching students how to praise and encourage one another in the same way staff members do, building a culture of peer-to-peer support. In addition, while students were able to demonstrate what they were learning, there is room to deepen their ability to articulate the why—helping them develop stronger metacognitive skills and ownership of their learning. Finally, refining classroom structures and procedures could further enhance effectiveness; for example, using a timer could support pacing, transitions, and student accountability.
A32: INTEGRATED ACTION PLAN
A33: Math Goal: Increase overall math achievement by 5% at Alice Vail Middle School by the end of the 2025 AASA testing period.
A34: Action Step (Instructional Practices): Alice Vail will achieve a targeted improvement in Math by the end of the 2025 AASA testing period. Key strategies include the use of iReady, IXL, and Benchmark assessments, along with weekly School City CFAs in Math and ELA. Students will monitor their progress, set individual goals, and celebrate growth. Teachers will align instruction with quarterly benchmarks and focus on coaching students on question types using resources from CSP. | B34: Progress: Teachers are implementing key strategies, including iReady, IXL, and Benchmark assessments, to provide differentiated instruction and ongoing skill reinforcement. Weekly School City CFAs in Math and ELA are helping monitor student growth and guide instructional adjustments. Students are actively tracking their own progress, setting individual goals, and celebrating achievements, which is fostering ownership of learning. Additionally, teachers are aligning instruction with quarterly benchmarks and providing targeted coaching on specific question types using resources from CSP, ensuring that instruction is focused, intentional, and data-driven.
A35: ELA Goal: Increase overall ELA achievement by 5% at Alice Vail Middle School by the end of the 2025 AASA testing period.
A36: Action Step (Instructional Practices): Alice Vail will achieve a targeted improvement in ELA by the end of the 2025 AASA testing period. Key strategies include the use of iReady, IXL, and Benchmark assessments, along with weekly School City CFAs in Math and ELA. Students will monitor their progress, set individual goals, and celebrate growth. Teachers will align instruction with quarterly benchmarks and focus on coaching students on question types using resources from CSP. | B36: Progress: Alice Vail is making steady progress toward the targeted improvement in ELA for the 2025 AASA testing period. Teachers are using iReady, IXL, and Benchmark assessments to guide instruction and differentiate support for students. Weekly School City CFAs in Math and ELA provide timely data to monitor growth and inform instructional adjustments. Students are actively tracking their progress, setting individual goals, and celebrating achievements, which promotes ownership of their learning. Instruction is aligned with quarterly benchmarks, and teachers are providing targeted coaching on question types using CSP resources to ensure focused, strategic support for student success.
A37: Additional Goal:By the end of the school year, staff will finalize a plan to support high academic and behavioral expectations for all students, aiming for a reduction in referrals and an increase in academic achievement on benchmark assessments.
A38: Action Step: The Data Review Team will focus on behavioral trends and strategically plan supports to improve school culture and climate, including SSS. Title funds will be used to support SSS. | B38: Progress: Data literacy has been a major focus at the school, enabling staff to make informed decisions, track progress, and adjust interventions in a timely and effective manner. These efforts are fostering a more positive, structured, and academically focused environment for all students.
A40: TRIPLE CROWN - SCHOOL SUMMARY
A41: High Quality Instruction
A42: 1. What are some current instructional focus areas for your school? Current instructional focus areas include incorporating common formative assessments (CFAs) in ELA and Science, with a goal to expand this practice school-wide. The school is implementing a variety of strategies to support student learning, including project-based learning, the NSGX model, team-based models, guided reading, intentional grouping, differentiated instruction, and effective use of teaching assistants. Core enrichment is going very well, leveraging teacher strengths to positively impact student outcomes. Sixth grade classrooms are integrating AVID strategies, and the arts department is collaborating across all middle schools, with high school students tutoring middle schoolers on Thursdays. Additional initiatives include Future Falcon Night in January, support from a restorative practices facilitator, a strong partnership with ASPIRE, and active parent engagement through the PTSA. Student well-being is also a priority, as evidenced by 100% student participation in a recent vape prevention presentation. 2. What are your expectations for teachers using Learning Targets & Success Criteria? All teachers are expected to have learning targets and success criteria posted consistently. This ensures clarity for students, supports instructional alignment, and promotes student ownership of learning. 3. Identify 1 area of strength and 1 area of growth related to Student Engagement at your school. Strength: High levels of student engagement are evident across classrooms, with students actively participating in learning activities. Growth: Continue to increase engagement in all classes by modeling expectations, providing examples, and being actively present to guide students.
...

Sheet Fall 2 - Data 
A1: Spring Semester Walkthrough | D1: School: | E1: =Cover!F27 -> Alice Vail | G1: Date: | H1: =Cover!F33 -> 0
A4: CORE | B4: Classroom Environment | C4: Learning Expectations | D4: Student Thinking, Problem Solving, Voice | E4: Engaging Students in Learning | F4: Assessment in Instruction | G4: Flexibility and Responsiveness | H4: Integrity of Core Curriculum | I4: Culturally Relevant | J4: Culturally Relevant Curriculum | K4: CR Pedagogy, Critical Thinking | L4: Positive Learning Community | M4: Student Identity and Voice | N4: Language Acquisition | O4: English Language Development | P4: Cultural Responsiveness | Q4: Student Grouping, Language Use | R4: Career & Tech Education | S4: Classroom Instruction | T4: Lab Instruction | U4: Exceptional Education | V4: Classroom Instruction | W4: Magnet | X4: Instructional Focus | Y4: Magnet Specific | Z4: Community Engagement | AA4: Two-Way Dual Language | AB4: Language Development | AC4: Cultural Competence
A5: Indicators Average Score | B5: =IFERROR(TEXT(AVERAGE(B9:B42),"##.00")&" out of 4","No Data") -> 7.80 out of 4 | C5: =IFERROR(TEXT(AVERAGE(C9:C42),"##.00")&" out of 6","No Data") -> 3.30 out of 6 | D5: =IFERROR(TEXT(AVERAGE(D9:D42),"##.00")&" out of 5","No Data") -> 2.60 out of 5 | E5: =IFERROR(TEXT(AVERAGE(E9:E42),"##.00")&" out of 6","No Data") -> 3.60 out of 6 | F5: =IFERROR(TEXT(AVERAGE(F9:F42),"##.00")&" out of 4","No Data") -> 2.10 out of 4 | G5: =IFERROR(TEXT(AVERAGE(G9:G42),"##.00")&" out of 5","No Data") -> 3.20 out of 5 | H5: =IFERROR(TEXT(AVERAGE(H9:H42),"##.00")&" out of 3","No Data") -> 1.70 out of 3 | J5: =IFERROR(TEXT(AVERAGE(J9:J42),"##.00")&" out of 5","No Data") -> No Data | K5: =IFERROR(TEXT(AVERAGE(K9:K42),"##.00")&" out of 4","No Data") -> No Data | L5: =IFERROR(TEXT(AVERAGE(L9:L42),"##.00")&" out of 2","No Data") -> No Data | M5: =IFERROR(TEXT(AVERAGE(M9:M42),"##.00")&" out of 2","No Data") -> No Data | O5: =IFERROR(TEXT(AVERAGE(O9:O42),"##.00")&" out of 4","No Data") -> No Data | P5: =IFERROR(TEXT(AVERAGE(P9:P42),"##.00")&" out of 2","No Data") -> No Data | Q5: =IFERROR(TEXT(AVERAGE(Q9:Q42),"##.00")&" out of 2","No Data") -> No Data | S5: =IFERROR(TEXT(AVERAGE(S9:S42),"##.00")&" out of 3","No Data") -> No Data | T5: =IFERROR(TEXT(AVERAGE(T9:T42),"##.00")&" out of 3","No Data") -> No Data | V5: =IFERROR(TEXT(AVERAGE(V9:V42),"##.00")&" out of 2","No Data") -> No Data | X5: =IFERROR(TEXT(AVERAGE(X9:X42),"##.00")&" out of 5","No Data") -> No Data | Y5: =IFERROR(TEXT(AVERAGE(Y9:Y42),"##.00")&" out of 3","No Data") -> No Data | Z5: =IFERROR(TEXT(AVERAGE(Z9:Z42),"##.00")&" out of 2","No Data") -> No Data | AB5: =IFERROR(TEXT(AVERAGE(AB9:AB42),"##.00")&" out of 5","No Data") -> No Data | AC5: =IFERROR(TEXT(AVERAGE(AC9:AC42),"##.00")&" out of 4","No Data") -> No Data
A6: % of Indicators Observed | B6: =IFERROR(AVERAGE(B9:B42)/4,"No Data") -> 1.95 | C6: =IFERROR(AVERAGE(C9:C42)/6,"No Data") -> 0.55 | D6: =IFERROR(AVERAGE(D9:D42)/5,"No Data") -> 0.52 | E6: =IFERROR(AVERAGE(E9:E42)/7,"No Data") -> 0.51428571 | F6: =IFERROR(AVERAGE(F9:F42)/4,"No Data") -> 0.525 | G6: =IFERROR(AVERAGE(G9:G42)/5,"No Data") -> 0.64 | H6: =IFERROR(AVERAGE(H9:H42)/3,"No Data") -> 0.56666667 | J6: =IFERROR(AVERAGE(J9:J42)/5,"No Data") -> No Data | K6: =IFERROR(AVERAGE(K9:K42)/4,"No Data") -> No Data | L6: =IFERROR(AVERAGE(L9:L42)/2,"No Data") -> No Data | M6: =IFERROR(AVERAGE(M9:M42)/2,"No Data") -> No Data | O6: =IFERROR(AVERAGE(O9:O42)/4,"No Data") -> No Data | P6: =IFERROR(AVERAGE(P9:P42)/2,"No Data") -> No Data | Q6: =IFERROR(AVERAGE(Q9:Q42)/2,"No Data") -> No Data | S6: =IFERROR(AVERAGE(S9:S42)/3,"No Data") -> No Data | T6: =IFERROR(AVERAGE(T9:T42)/3,"No Data") -> No Data | V6: =IFERROR(AVERAGE(V9:V42)/2,"No Data") -> No Data | X6: =IFERROR(AVERAGE(X9:X42)/5,"No Data") -> No Data | Y6: =IFERROR(AVERAGE(Y9:Y42)/3,"No Data") -> No Data | Z6: =IFERROR(AVERAGE(Z9:Z42)/2,"No Data") -> No Data | AB6: =IFERROR(AVERAGE(AB9:AB42)/5,"No Data") -> No Data | AC6: =IFERROR(AVERAGE(AC9:AC42)/4,"No Data") -> No Data
A8: CORE | B8: Classroom Environment (#of indicators = 0-4) | C8: Learning Expectations (# of Indicators = 0-6) | D8: Student Thinking, Problem Solving, Voice (# of Indicators = 0-5) | E8: Engaging Students in Learning (# of Indicators = 0-6) | F8: Assessment in Instruction (# of Indicators = 0-4) | G8: Flexibility and Responsiveness (# of Indicators = 0-5) | H8: Integrity of Core Curriculum (# of Indicators = 0-3) | I8: Culturally Relevant | J8: Culturally Relevant Curriculum (#of Indicators= 0-5) | K8: CR Pedagogy, Critical Thinking (#of Indicators 0-4) | L8: Positive Learning Community (#of Indicators 0-2) | M8: Student Identity and Voice (#of Indicators 0-2) | N8: Language Acquisition | O8: English Language Development (ELD) Instruction = 0-4) | P8: Cultural Responsiveness (#of Indicators 0-2) | Q8: Student Grouping, Language Use (#of Indicators 0-2) | R8: Career & Tech Education | S8: Classroom Instruction (#of Indicators= 0-3) | T8: Lab Instruction (#of Indicators 0-3) | U8: Exceptional Education | V8: Classroom Instruction (#of Indicators= 0-2) | W8: Magnet | X8: Instructional Focus (#of Indicators= 0-5) | Y8: Magnet Specific (#of Indicators 0-3) | Z8: Community Engagement (#of Indicators 0-2) | AA8: Two-Way Dual Language | AB8: Language Development (#of Indicators= 0-5) | AC8: Cultural Competence (#of Indicators 0-4)
A9: Classroom 1 | B9: 2 | C9: 2 | D9: 2 | E9: 2 | F9: 1 | G9: 2 | H9: 0
A10: Classroom 2 | B10: 4 | C10: 0 | D10: 3 | E10: 3 | F10: 2 | G10: 4 | H10: 1
A11: Classroom 3 | B11: 3 | C11: 0 | D11: 2 | E11: 3 | F11: 1 | G11: 5 | H11: 2
A12: Classroom 4 | B12: 2 | C12: 1 | D12: 2 | E12: 2 | F12: 1 | G12: 2 | H12: 3
A13: Classroom 5 | B13: 4 | C13: 6 | D13: 4 | E13: 6 | F13: 4 | G13: 5 | H13: 3
A14: Classroom 6 | B14: 3 | C14: 4 | D14: 0 | E14: 1 | F14: 1 | G14: 1 | H14: 0
A15: Classroom 7 | B15: 4 | C15: 6 | D15: 4 | E15: 6 | F15: 4 | G15: 5 | H15: 3
A16: Classroom 8 | B16: 51 | C16: 6 | D16: 4 | E16: 5 | F16: 3 | G16: 2 | H16: 1
A17: Classroom 9 | B17: 3 | C17: 6 | D17: 4 | E17: 6 | F17: 4 | G17: 5 | H17: 2
A18: Classroom 10 | B18: 2 | C18: 2 | D18: 1 | E18: 2 | F18: 0 | G18: 1 | H18: 2
A19: Classroom 11
A20: Classroom 12
A21: Classroom 13
A22: Classroom 14
A23: Classroom 15
A24: Classroom 16
A25: Classroom 17
A26: Classroom 18
A27: Classroom 19
A28: Classroom 20
A29: Classroom 21
A30: Classroom 22
... A42: Classroom 34
A43: Total Percent Earned | B43: =B6 -> 1.95 | C43: =C6 -> 0.55 | D43: =D6 -> 0.52 | E43: =E6 -> 0.51428571 | F43: =F6 -> 0.525 | G43: =G6 -> 0.64 | H43: =H6 -> 0.56666667 | J43: =J6 -> No Data | K43: =K6 -> No Data | L43: =L6 -> No Data | M43: =M6 -> No Data | O43: =O6 -> No Data | P43: =P6 -> No Data | Q43: =Q6 -> No Data | S43: =S6 -> No Data | T43: =T6 -> No Data | V43: =V6 -> No Data | X43: =X6 -> No Data | Y43: =Y6 -> No Data | Z43: =Z6 -> No Data | AB43: =AB6 -> No Data | AC43: =AC6 -> No Data

Sheet Fall 2- Report 
A1: District Walkthrough - Report
A2: =_xlfn.CONCAT("School: ",Cover!F27) -> School: Alice Vail | B2: =Cover!F33 -> 0
A4: CORE CATEGORIES - TEAM SUMMARY
A5: Classroom Environment | B5: =IFERROR('Fall 2 - Data '!B6,"No Data") -> 1.95
A6: Learning Expectations | B6: =IFERROR('Fall 2 - Data '!C6,"No Data") -> 0.55
A7: Student Thinking, Problem Solving, Voice | B7: =IFERROR('Fall 2 - Data '!D6,"No Data") -> 0.52
A8: Engaging Students in Learning | B8: =IFERROR('Fall 2 - Data '!E6,"No Data") -> 0.51428571
A9: Assessment in Instruction | B9: =IFERROR('Fall 2 - Data '!F6,"No Data") -> 0.525
A10: Flexibility and Responsiveness | B10: =IFERROR('Fall 2 - Data '!G6,"No Data") -> 0.64
A11: Integrity of Core Curriculum | B11: =IFERROR('Fall 2 - Data '!H6,"No Data") -> 0.56666667
A12: PRAISE | B12: PROBE & PUSH
A13: *Active participation and student centered engagement. Rubrics that were used consistently in all classes. | B13: *Can students be structured to allow for even more student to student discussion? Leverage curriculum so that it facilitates and fosters student to student collaboration. Adhere to AVID curriculum specifically.
A14: *Structure, routines, and positive rapport between students and teachers. Use of stations in one class. | B14: *Posting learning targets and succcess criteria for stations. More emphasis on students leading discussion with math concepts. How can we make instruction more accessible for students? What other strategies can be used in terms of differentiation?
A15: *Classrooms set up for group learning with tables and chairs. Teachers have good rapport with students. | B15: *Leverage student to student moments that occur.
A16: PRINCIPAL REFLECTION & NEXT STEPS
A19: CULTURALLY RESPONSIVE INSTRUCTION - TEAM SUMMARY
A20: Culturally Relevant Curriculum | B20: ='Fall 2 - Data '!J6 -> No Data
A21: CR Pedagogy & Critical Thinking | B21: ='Fall 2 - Data '!K6 -> No Data
A22: Positive Learning Community | B22: ='Fall 2 - Data '!L6 -> No Data
A23: Student Identity and Voice | B23: ='Fall 2 - Data '!M6 -> No Data
A24: PRAISE | B24: PROBE & PUSH
A25: * * * | B25: * * *
A26: DEPARTMENT NARRATIVE
A27: * * *
A29: LANGUAGE ACQUISITION - TEAM SUMMARY
A30: English Language Development Instruction | B30: ='Fall 2 - Data '!O6 -> No Data
A31: Cultural Responsiveness | B31: ='Fall 2 - Data '!P6 -> No Data
A32: Student Grouping and Language Use | B32: ='Fall 2 - Data '!Q6 -> No Data
A33: PRAISE | B33: PROBE & PUSH
A34: * * * | B34: * * *
A35: DEPARTMENT NARRATIVE
A38: CAREER & TECHNICAL EDUCATION - TEAM SUMMARY
A39: Classroom Instruction | B39: ='Fall 2 - Data '!S6 -> No Data
A40: Lab Instruction | B40: ='Fall 2 - Data '!T6 -> No Data
A41: PRAISE | B41: PROBE & PUSH
A42: * * * | B42: * * *
A43: DEPARTMENT NARRATIVE
A46: EXCEPTIONAL EDUCATION - TEAM SUMMARY
A47: Classroom Instruction | B47: ='Fall 2 - Data '!V6 -> No Data
A48: PRAISE | B48: PROBE & PUSH
...

Sheet Charts
AF24: Fall | AG24: Spring | AH24: Difference
AE25: Classroom Environment | AF25: ='Fall - Data'!B6 -> 0.9 | AG25: ='Fall 2 - Data '!B6 -> 1.95 | AH25: =IFERROR(AF25-AG25,"No Data") -> -1.05
AE26: Learning Expectations | AF26: ='Fall - Data'!C6 -> 0.83333333 | AG26: ='Fall 2 - Data '!C6 -> 0.55 | AH26: =IFERROR(AF26-AG26,"No Data") -> 0.28333333
AE27: Student Thinking, Problem Solving, Voice | AF27: ='Fall - Data'!D6 -> 0.56 | AG27: ='Fall 2 - Data '!D6 -> 0.52 | AH27: =IFERROR(AF27-AG27,"No Data") -> 0.04
AE28: Engaging Students in Learning | AF28: ='Fall - Data'!E6 -> 0.71666667 | AG28: ='Fall 2 - Data '!E6 -> 0.51428571 | AH28: =IFERROR(AF28-AG28,"No Data") -> 0.20238095
AE29: Assessment in Instruction | AF29: ='Fall - Data'!F6 -> 0.6 | AG29: ='Fall 2 - Data '!F6 -> 0.525 | AH29: =IFERROR(AF29-AG29,"No Data") -> 0.075
AE30: Flexibility and Responsiveness | AF30: ='Fall - Data'!G6 -> 0.62 | AG30: ='Fall 2 - Data '!G6 -> 0.64 | AH30: =IFERROR(AF30-AG30,"No Data") -> -0.02
AE31: Integrity of Core Curriculum | AF31: ='Fall - Data'!H6 -> 0.93333333 | AG31: ='Fall 2 - Data '!H6 -> 0.56666667 | AH31: =IFERROR(AF31-AG31,"No Data") -> 0.36666667

Sheet A & E School Report

Sheet Attendance
A1: Joshua Peebles
A2: Sonia Arvayo
A3: Heather Patty
A4: Kit Giuffre
A5: Tawnee Arrieta
A6: Shayla Samuels
A7: Ben Kowalski
A8: Melissa Hershey
A9: Brian Moreno
A10: Amber Clark
A11: Hillary Lotz
A12: Shawna Rodriguez
